<?xml version="1.0" encoding="utf-8"?>
<!-- This URDF was automatically created by SolidWorks to URDF Exporter! Originally created by Stephen Brawner (brawner@gmail.com) 
     Commit Version: 1.6.0-4-g7f85cfe  Build Version: 1.6.7995.38578
     For more information, please see http://wiki.ros.org/sw_urdf_exporter -->
<robot
  name="HAND_ASSEMBLY_w_tip">
  <link
    name="Palm_Base">
    <inertial>
      <origin
        xyz="-0.00103400900285897 -0.000180539094809852 0.0474435139934218"
        rpy="0 0 0" />
      <mass
        value="0.0923260250366322" />
      <inertia
        ixx="0.00015783467129876"
        ixy="1.67552395000014E-06"
        ixz="2.03624787383231E-06"
        iyy="0.000112349532484309"
        iyz="-3.30084225768315E-06"
        izz="7.70769956188042E-05" />
    </inertial>
    <visual>
      <origin
        xyz="0 0 0"
        rpy="0 0 0" />
      <geometry>
        <mesh
          filename="Palm_Base.STL" />
      </geometry>
      <material
        name="">
        <color
          rgba="0.752941176470588 0.752941176470588 0.752941176470588 1" />
      </material>
    </visual>
    <collision>
      <origin
        xyz="0 0 0"
        rpy="0 0 0" />
      <geometry>
        <mesh
          filename="Palm_Base.STL" />
      </geometry>
    </collision>
  </link>
  <link
    name="T_CMC">
    <inertial>
      <origin
        xyz="-0.0177528743407777 0.00210709032429534 0.00172578328714319"
        rpy="0 0 0" />
      <mass
        value="0.00466274355739475" />
      <inertia
        ixx="5.91068337186523E-07"
        ixy="1.22100042338684E-07"
        ixz="7.66648747890101E-08"
        iyy="1.15532024570322E-06"
        iyz="8.72417776166709E-09"
        izz="1.05459263052673E-06" />
    </inertial>
    <visual>
      <origin
        xyz="0 0 0"
        rpy="0 0 0" />
      <geometry>
        <mesh
          filename="T_CMC.STL" />
      </geometry>
      <material
        name="">
        <color
          rgba="1 1 1 1" />
      </material>
    </visual>
    <collision>
      <origin
        xyz="0 0 0"
        rpy="0 0 0" />
      <geometry>
        <mesh
          filename="T_CMC.STL" />
      </geometry>
    </collision>
  </link>
  <joint
    name="T_CMC"
    type="revolute">
    <origin
      xyz="0.0115599999999981 0.0263657188690824 0.0345742378610531"
      rpy="-3.08545108813298 -0.146781499054298 -1.9376645639798" />
    <parent
      link="Palm_Base" />
    <child
      link="T_CMC" />
    <axis
      xyz="0 0 1" />
    <limit
      lower="0"
      upper="1.8545"
      effort="10"
      velocity="0" />
  </joint>
  <link
    name="T_MCP">
    <inertial>
      <origin
        xyz="-0.0117195543506135 0.0142292379065931 7.95619311620005E-06"
        rpy="0 0 0" />
      <mass
        value="0.0033547197974598" />
      <inertia
        ixx="5.26043145167794E-07"
        ixy="9.04812058339906E-08"
        ixz="-8.47222922629862E-10"
        iyy="4.82729259847219E-07"
        iyz="8.57465672525974E-10"
        izz="6.36180921499929E-07" />
    </inertial>
    <visual>
      <origin
        xyz="0 0 0"
        rpy="0 0 0" />
      <geometry>
        <mesh
          filename="T_MCP.STL" />
      </geometry>
      <material
        name="">
        <color
          rgba="1 1 1 1" />
      </material>
    </visual>
    <collision>
      <origin
        xyz="0 0 0"
        rpy="0 0 0" />
      <geometry>
        <mesh
          filename="T_MCP.STL" />
      </geometry>
    </collision>
  </link>
  <joint
    name="T_MCP"
    type="revolute">
    <origin
      xyz="-0.0469999941010945 0.00706933481126965 0.00842490515858201"
      rpy="0.134387415062573 -0.865005439816257 1.39498933884904" />
    <parent
      link="T_CMC" />
    <child
      link="T_MCP" />
    <axis
      xyz="0 0 1" />
    <limit
      lower="0"
      upper="0.9203"
      effort="10"
      velocity="0" />
  </joint>
  <link
    name="T_IP">
    <inertial>
      <origin
        xyz="-0.0154710251108717 0.0116628328499748 -1.39141450905822E-05"
        rpy="0 0 0" />
      <mass
        value="0.00427950857548729" />
      <inertia
        ixx="4.55363913450062E-07"
        ixy="1.71115890432477E-07"
        ixz="7.03068336447427E-11"
        iyy="4.33364739226157E-07"
        iyz="2.79946493298776E-10"
        izz="5.83632941087751E-07" />
    </inertial>
    <visual>
      <origin
        xyz="0 0 0"
        rpy="0 0 0" />
      <geometry>
        <mesh
          filename="T_IP.STL" />
      </geometry>
      <material
        name="">
        <color
          rgba="1 1 1 1" />
      </material>
    </visual>
    <collision>
      <origin
        xyz="0 0 0"
        rpy="0 0 0" />
      <geometry>
        <mesh
          filename="T_IP.STL" />
      </geometry>
    </collision>
  </link>
  <joint
    name="T_IP"
    type="revolute">
    <origin
      xyz="-0.011834 0.038209 0"
      rpy="0 0 0" />
    <parent
      link="T_MCP" />
    <child
      link="T_IP" />
    <axis
      xyz="0 0 1" />
    <limit
      lower="0"
      upper="0.7858"
      effort="10"
      velocity="0" />
  </joint>
  <link
    name="T_IP_TIP">
    <inertial>
      <origin
        xyz="0.0103691008973476 -0.015362481770586 -1.39141450904955E-05"
        rpy="0 0 0" />
      <mass
        value="0.0042795085754873" />
      <inertia
        ixx="4.55363913450062E-07"
        ixy="1.71115890432475E-07"
        ixz="7.03068336449413E-11"
        iyy="4.33364739226156E-07"
        iyz="2.79946493298683E-10"
        izz="5.83632941087752E-07" />
    </inertial>
    <visual>
      <origin
        xyz="0 0 0"
        rpy="0 0 0" />
      <geometry>
        <mesh
          filename="T_IP_TIP.STL" />
      </geometry>
      <material
        name="">
        <color
          rgba="1 1 1 1" />
      </material>
    </visual>
    <collision>
      <origin
        xyz="0 0 0"
        rpy="0 0 0" />
      <geometry>
        <mesh
          filename="T_IP_TIP.STL" />
      </geometry>
    </collision>
  </link>
  <joint
    name="T_IP_tip"
    type="fixed">
    <origin
      xyz="-0.02584 0.027025 0"
      rpy="0 0 0" />
    <parent
      link="T_IP" />
    <child
      link="T_IP_TIP" />
    <axis
      xyz="0 0 0" />
  </joint>
  <link
    name="I_B_MCP">
    <inertial>
      <origin
        xyz="-0.000141740995557887 0.00741427693562444 0.00589412532435988"
        rpy="0 0 0" />
      <mass
        value="0.00533430750029796" />
      <inertia
        ixx="1.03059700939786E-06"
        ixy="2.85492272449384E-09"
        ixz="5.92070466417556E-09"
        iyy="6.30910124394686E-07"
        iyz="-3.26746600649069E-07"
        izz="8.35250160642294E-07" />
    </inertial>
    <visual>
      <origin
        xyz="0 0 0"
        rpy="0 0 0" />
      <geometry>
        <mesh
          filename="I_B_MCP.STL" />
      </geometry>
      <material
        name="">
        <color
          rgba="0.698039215686274 0.698039215686274 0.698039215686274 1" />
      </material>
    </visual>
    <collision>
      <origin
        xyz="0 0 0"
        rpy="0 0 0" />
      <geometry>
        <mesh
          filename="I_B_MCP.STL" />
      </geometry>
    </collision>
  </link>
  <joint
    name="I_B_MCP"
    type="revolute">
    <origin
      xyz="0 0.0315 0.101"
      rpy="1.5708 0 -1.5708" />
    <parent
      link="Palm_Base" />
    <child
      link="I_B_MCP" />
    <axis
      xyz="0 0 1" />
    <limit
      lower="0"
      upper="0.4666"
      effort="0"
      velocity="0" />
  </joint>
  <link
    name="I_MCP">
    <inertial>
      <origin
        xyz="1.74845297286758E-05 0.0124250824596619 -0.00584261155744063"
        rpy="0 0 0" />
      <mass
        value="0.002755942184203" />
      <inertia
        ixx="3.71398920418385E-07"
        ixy="4.40724760944911E-11"
        ixz="5.10520634416052E-11"
        iyy="2.52622034069185E-07"
        iyz="-4.7152595339951E-08"
        izz="3.66973305602765E-07" />
    </inertial>
    <visual>
      <origin
        xyz="0 0 0"
        rpy="0 0 0" />
      <geometry>
        <mesh
          filename="I_MCP.STL" />
      </geometry>
      <material
        name="">
        <color
          rgba="0.796078431372549 0.823529411764706 0.937254901960784 1" />
      </material>
    </visual>
    <collision>
      <origin
        xyz="0 0 0"
        rpy="0 0 0" />
      <geometry>
        <mesh
          filename="I_MCP.STL" />
      </geometry>
    </collision>
  </link>
  <joint
    name="I_MCP"
    type="revolute">
    <origin
      xyz="0 0.0279999999999992 0.0105000000000001"
      rpy="0 0 0" />
    <parent
      link="I_B_MCP" />
    <child
      link="I_MCP" />
    <axis
      xyz="-1 0 0" />
    <limit
      lower="0"
      upper="1.8002"
      effort="0"
      velocity="0" />
  </joint>
  <link
    name="I_PIP">
    <inertial>
      <origin
        xyz="1.91322862936327E-05 0.0102728432221988 -0.00621243408785706"
        rpy="0 0 0" />
      <mass
        value="0.00237210892394421" />
      <inertia
        ixx="2.39005004655723E-07"
        ixy="3.37006733460047E-11"
        ixz="3.67682453100147E-11"
        iyy="2.02579627119824E-07"
        iyz="-3.33240723310074E-09"
        izz="2.33279497210016E-07" />
    </inertial>
    <visual>
      <origin
        xyz="0 0 0"
        rpy="0 0 0" />
      <geometry>
        <mesh
          filename="I_PIP.STL" />
      </geometry>
      <material
        name="">
        <color
          rgba="0.796078431372549 0.823529411764706 0.937254901960784 1" />
      </material>
    </visual>
    <collision>
      <origin
        xyz="0 0 0"
        rpy="0 0 0" />
      <geometry>
        <mesh
          filename="I_PIP.STL" />
      </geometry>
    </collision>
  </link>
  <joint
    name="I_PIP"
    type="revolute">
    <origin
      xyz="0 0.0349845407392164 -4.41133227821362E-05"
      rpy="0 0 0" />
    <parent
      link="I_MCP" />
    <child
      link="I_PIP" />
    <axis
      xyz="-1 0 0" />
    <limit
      upper="1.3104"
      lower="0"
      effort="0"
      velocity="0" />
  </joint>
  <link
    name="I_DIP">
    <inertial>
      <origin
        xyz="0.00887453911689197 0.0186542942734911 1.79511034709562E-05"
        rpy="0 0 0" />
      <mass
        value="0.00401062179385268" />
      <inertia
        ixx="5.63158594739122E-07"
        ixy="-6.20177624878477E-08"
        ixz="2.95049292892786E-11"
        iyy="2.03576120686417E-07"
        iyz="2.56006508686644E-10"
        izz="5.37383345412659E-07" />
    </inertial>
    <visual>
      <origin
        xyz="0 0 0"
        rpy="0 0 0" />
      <geometry>
        <mesh
          filename="I_DIP.STL" />
      </geometry>
      <material
        name="">
        <color
          rgba="0.796078431372549 0.823529411764706 0.937254901960784 1" />
      </material>
    </visual>
    <collision>
      <origin
        xyz="0 0 0"
        rpy="0 0 0" />
      <geometry>
        <mesh
          filename="I_DIP.STL" />
      </geometry>
    </collision>
  </link>
  <joint
    name="I_DIP"
    type="revolute">
    <origin
      xyz="0 0.028 0"
      rpy="0 1.5707963267949 0" />
    <parent
      link="I_PIP" />
    <child
      link="I_DIP" />
    <axis
      xyz="0 0 -1" />
    <limit
      upper="1.1885"
      lower="0"
      effort="0"
      velocity="0" />
  </joint>
  <link
    name="I_DIP_TIP">
    <inertial>
      <origin
        xyz="-0.00112546088310851 -0.0208457057265095 1.79511034683888E-05"
        rpy="0 0 0" />
      <mass
        value="0.00401062179385268" />
      <inertia
        ixx="5.63158594739121E-07"
        ixy="-6.20177624878477E-08"
        ixz="2.95049292892854E-11"
        iyy="2.03576120686417E-07"
        iyz="2.5600650868666E-10"
        izz="5.37383345412658E-07" />
    </inertial>
    <visual>
      <origin
        xyz="0 0 0"
        rpy="0 0 0" />
      <geometry>
        <mesh
          filename="I_DIP_TIP.STL" />
      </geometry>
      <material
        name="">
        <color
          rgba="0.796078431372549 0.823529411764706 0.937254901960784 1" />
      </material>
    </visual>
    <collision>
      <origin
        xyz="0 0 0"
        rpy="0 0 0" />
      <geometry>
        <mesh
          filename="I_DIP_TIP.STL" />
      </geometry>
    </collision>
  </link>
  <joint
    name="I_DIP_tip"
    type="fixed">
    <origin
      xyz="0.0100000000000005 0.0395000000000005 0"
      rpy="0 0 0" />
    <parent
      link="I_DIP" />
    <child
      link="I_DIP_TIP" />
    <axis
      xyz="0 0 0" />
  </joint>
  <link
    name="M_MCP">
    <inertial>
      <origin
        xyz="1.64022040103299E-05 0.0123174782088804 -0.00573714670375402"
        rpy="0 0 0" />
      <mass
        value="0.00272570986161072" />
      <inertia
        ixx="3.60741144993206E-07"
        ixy="4.96515705969676E-11"
        ixz="5.81346054455877E-11"
        iyy="2.49082764372577E-07"
        iyz="-4.63139493716337E-08"
        izz="3.60046128584186E-07" />
    </inertial>
    <visual>
      <origin
        xyz="0 0 0"
        rpy="0 0 0" />
      <geometry>
        <mesh
          filename="M_MCP.STL" />
      </geometry>
      <material
        name="">
        <color
          rgba="0.796078431372549 0.823529411764706 0.937254901960784 1" />
      </material>
    </visual>
    <collision>
      <origin
        xyz="0 0 0"
        rpy="0 0 0" />
      <geometry>
        <mesh
          filename="M_MCP.STL" />
      </geometry>
    </collision>
  </link>
  <joint
    name="M_MCP"
    type="revolute">
    <origin
      xyz="-0.010497 0.010499 0.138"
      rpy="1.5708 0 -1.5708" />
    <parent
      link="Palm_Base" />
    <child
      link="M_MCP" />
    <axis
      xyz="-1 0 0" />
    <limit
      upper="1.7791"
      lower="0"
      effort="0"
      velocity="0" />
  </joint>
  <link
    name="M_PIP">
    <inertial>
      <origin
        xyz="1.83008023570738E-05 0.0102838809467659 -0.00629710419392002"
        rpy="0 0 0" />
      <mass
        value="0.00233862559762926" />
      <inertia
        ixx="2.35929413226276E-07"
        ixy="-3.34829212476315E-13"
        ixz="3.71732498979706E-11"
        iyy="2.00832285337959E-07"
        iyz="-3.66556023160932E-09"
        izz="2.27074048207937E-07" />
    </inertial>
    <visual>
      <origin
        xyz="0 0 0"
        rpy="0 0 0" />
      <geometry>
        <mesh
          filename="M_PIP.STL" />
      </geometry>
      <material
        name="">
        <color
          rgba="0.792156862745098 0.819607843137255 0.933333333333333 1" />
      </material>
    </visual>
    <collision>
      <origin
        xyz="0 0 0"
        rpy="0 0 0" />
      <geometry>
        <mesh
          filename="M_PIP.STL" />
      </geometry>
    </collision>
  </link>
  <joint
    name="M_PIP"
    type="revolute">
    <origin
      xyz="0 0.0349845407392164 -4.41133227822368E-05"
      rpy="0 0 0" />
    <parent
      link="M_MCP" />
    <child
      link="M_PIP" />
    <axis
      xyz="-1 0 0" />
    <limit
      upper="1.2823"
      lower="0"
      effort="0"
      velocity="0" />
  </joint>
  <link
    name="M_DIP">
    <inertial>
      <origin
        xyz="0.00882563923105356 0.0186497288030855 1.91380464206088E-05"
        rpy="0 0 0" />
      <mass
        value="0.00393986039661757" />
      <inertia
        ixx="5.59716447859537E-07"
        ixy="-6.16509349274183E-08"
        ixz="2.3914122648095E-11"
        iyy="2.02161694696982E-07"
        iyz="2.54134288669402E-10"
        izz="5.33501898097562E-07" />
    </inertial>
    <visual>
      <origin
        xyz="0 0 0"
        rpy="0 0 0" />
      <geometry>
        <mesh
          filename="M_DIP.STL" />
      </geometry>
      <material
        name="">
        <color
          rgba="0.796078431372549 0.823529411764706 0.937254901960784 1" />
      </material>
    </visual>
    <collision>
      <origin
        xyz="0 0 0"
        rpy="0 0 0" />
      <geometry>
        <mesh
          filename="M_DIP.STL" />
      </geometry>
    </collision>
  </link>
  <joint
    name="M_DIP"
    type="revolute">
    <origin
      xyz="0 0.028 0"
      rpy="0 1.5707963267949 0" />
    <parent
      link="M_PIP" />
    <child
      link="M_DIP" />
    <axis
      xyz="0 0 -1" />
    <limit
      upper="1.275"
      lower="0"
      effort="0"
      velocity="0" />
  </joint>
  <link
    name="M_DIP_TIP">
    <inertial>
      <origin
        xyz="-0.00117436076894647 -0.0208502711969146 1.82879864194761E-05"
        rpy="0 0 0" />
      <mass
        value="0.00393986039661757" />
      <inertia
        ixx="5.59716447859538E-07"
        ixy="-6.16509349274183E-08"
        ixz="2.39141226480827E-11"
        iyy="2.02161694696982E-07"
        iyz="2.54134288669405E-10"
        izz="5.33501898097562E-07" />
    </inertial>
    <visual>
      <origin
        xyz="0 0 0"
        rpy="0 0 0" />
      <geometry>
        <mesh
          filename="M_DIP_TIP.STL" />
      </geometry>
      <material
        name="">
        <color
          rgba="0.796078431372549 0.823529411764706 0.937254901960784 1" />
      </material>
    </visual>
    <collision>
      <origin
        xyz="0 0 0"
        rpy="0 0 0" />
      <geometry>
        <mesh
          filename="M_DIP_TIP.STL" />
      </geometry>
    </collision>
  </link>
  <joint
    name="M_DIP_tip"
    type="fixed">
    <origin
      xyz="0.01 0.0395000000000001 0"
      rpy="0 0 0" />
    <parent
      link="M_DIP" />
    <child
      link="M_DIP_TIP" />
    <axis
      xyz="0 0 0" />
  </joint>
  <link
    name="R_B_MCP">
    <inertial>
      <origin
        xyz="0.000141400022495722 0.00748571390330596 -0.00591445143783573"
        rpy="0 0 0" />
      <mass
        value="0.00533806254719218" />
      <inertia
        ixx="1.03534831698766E-06"
        ixy="-2.71242837602829E-09"
        ixz="5.52800343097293E-09"
        iyy="6.29683236200971E-07"
        iyz="3.2850594953798E-07"
        izz="8.39889436290282E-07" />
    </inertial>
    <visual>
      <origin
        xyz="0 0 0"
        rpy="0 0 0" />
      <geometry>
        <mesh
          filename="R_B_MCP.STL" />
      </geometry>
      <material
        name="">
        <color
          rgba="0.698039215686274 0.698039215686274 0.698039215686274 1" />
      </material>
    </visual>
    <collision>
      <origin
        xyz="0 0 0"
        rpy="0 0 0" />
      <geometry>
        <mesh
          filename="R_B_MCP.STL" />
      </geometry>
    </collision>
  </link>
  <joint
    name="R_B_MCP"
    type="revolute">
    <origin
      xyz="0 -0.0105 0.101"
      rpy="1.5708 0 1.5708" />
    <parent
      link="Palm_Base" />
    <child
      link="R_B_MCP" />
    <axis
      xyz="0 0 1" />
    <limit
      lower="0"
      upper="0.4666"
      effort="0"
      velocity="0" />
  </joint>
  <link
    name="R_MCP">
    <inertial>
      <origin
        xyz="1.81899888161037E-05 0.012359374141564 -0.00587054662659402"
        rpy="0 0 0" />
      <mass
        value="0.00276772093942441" />
      <inertia
        ixx="3.62933389029114E-07"
        ixy="2.6008141899167E-11"
        ixz="4.37192594293451E-11"
        iyy="2.51940280505407E-07"
        iyz="-4.485013942002E-08"
        izz="3.63178789330102E-07" />
    </inertial>
    <visual>
      <origin
        xyz="0 0 0"
        rpy="0 0 0" />
      <geometry>
        <mesh
          filename="R_MCP.STL" />
      </geometry>
      <material
        name="">
        <color
          rgba="0.796078431372549 0.823529411764706 0.937254901960784 1" />
      </material>
    </visual>
    <collision>
      <origin
        xyz="0 0 0"
        rpy="0 0 0" />
      <geometry>
        <mesh
          filename="R_MCP.STL" />
      </geometry>
    </collision>
  </link>
  <joint
    name="R_MCP"
    type="revolute">
    <origin
      xyz="0 0.028 -0.0104999999999996"
      rpy="-3.14159265358979 0 3.14159265358979" />
    <parent
      link="R_B_MCP" />
    <child
      link="R_MCP" />
    <axis
      xyz="-1 0 0" />
    <limit
      upper="1.7553"
      lower="0"
      effort="0"
      velocity="0" />
  </joint>
  <link
    name="R_PIP">
    <inertial>
      <origin
        xyz="1.82711535064734E-05 0.0103252304355741 -0.00628747443583766"
        rpy="0 0 0" />
      <mass
        value="0.00234637206717096" />
      <inertia
        ixx="2.36074471265145E-07"
        ixy="7.75187690713442E-12"
        ixz="1.58152430107811E-11"
        iyy="2.01399401299825E-07"
        iyz="-3.30872238950386E-09"
        izz="2.28648255064159E-07" />
    </inertial>
    <visual>
      <origin
        xyz="0 0 0"
        rpy="0 0 0" />
      <geometry>
        <mesh
          filename="R_PIP.STL" />
      </geometry>
      <material
        name="">
        <color
          rgba="0.796078431372549 0.823529411764706 0.937254901960784 1" />
      </material>
    </visual>
    <collision>
      <origin
        xyz="0 0 0"
        rpy="0 0 0" />
      <geometry>
        <mesh
          filename="R_PIP.STL" />
      </geometry>
    </collision>
  </link>
  <joint
    name="R_PIP"
    type="revolute">
    <origin
      xyz="0 0.0349845407392164 -4.41133227817875E-05"
      rpy="0 0 0" />
    <parent
      link="R_MCP" />
    <child
      link="R_PIP" />
    <axis
      xyz="-1 0 0" />
    <limit
      upper="1.273"
      lower="0"
      effort="0"
      velocity="0" />
  </joint>
  <link
    name="R_DIP">
    <inertial>
      <origin
        xyz="0.00880902130280509 0.0186629668952652 1.83062358519743E-05"
        rpy="0 0 0" />
      <mass
        value="0.00392874816769408" />
      <inertia
        ixx="5.5954543559867E-07"
        ixy="-6.18615159431051E-08"
        ixz="2.41650917133391E-11"
        iyy="2.0175897351784E-07"
        iyz="2.5578789547633E-10"
        izz="5.33046408962186E-07" />
    </inertial>
    <visual>
      <origin
        xyz="0 0 0"
        rpy="0 0 0" />
      <geometry>
        <mesh
          filename="R_DIP.STL" />
      </geometry>
      <material
        name="">
        <color
          rgba="0.796078431372549 0.823529411764706 0.937254901960784 1" />
      </material>
    </visual>
    <collision>
      <origin
        xyz="0 0 0"
        rpy="0 0 0" />
      <geometry>
        <mesh
          filename="R_DIP.STL" />
      </geometry>
    </collision>
  </link>
  <joint
    name="R_DIP"
    type="revolute">
    <origin
      xyz="0 0.028 0"
      rpy="0 1.5707963267949 0" />
    <parent
      link="R_PIP" />
    <child
      link="R_DIP" />
    <axis
      xyz="0 0 -1" />
    <limit
      upper="1.2842"
      lower="0"
      effort="0"
      velocity="0" />
  </joint>
  <link
    name="R_DIP_TIP">
    <inertial>
      <origin
        xyz="-0.00119097799471922 -0.020837030942089 1.8306400363521E-05"
        rpy="0 0 0" />
      <mass
        value="0.00392874891708615" />
      <inertia
        ixx="5.59545595893736E-07"
        ixy="-6.18615594670326E-08"
        ixz="2.41567546999687E-11"
        iyy="2.01758965447605E-07"
        iyz="2.55755267014244E-10"
        izz="5.33046577522925E-07" />
    </inertial>
    <visual>
      <origin
        xyz="0 0 0"
        rpy="0 0 0" />
      <geometry>
        <mesh
          filename="R_DIP_TIP.STL" />
      </geometry>
      <material
        name="">
        <color
          rgba="0.796078431372549 0.823529411764706 0.937254901960784 1" />
      </material>
    </visual>
    <collision>
      <origin
        xyz="0 0 0"
        rpy="0 0 0" />
      <geometry>
        <mesh
          filename="R_DIP_TIP.STL" />
      </geometry>
    </collision>
  </link>
  <joint
    name="R_DIP_tip"
    type="fixed">
    <origin
      xyz="0.0100000000000002 0.0395 0"
      rpy="0 0 0" />
    <parent
      link="R_DIP" />
    <child
      link="R_DIP_TIP" />
    <axis
      xyz="0 0 0" />
  </joint>
  <link
    name="P_B_MCP">
    <inertial>
      <origin
        xyz="-0.000168227144883799 0.00805589897425299 -0.00620012472926412"
        rpy="0 0 0" />
      <mass
        value="0.00512816464476323" />
      <inertia
        ixx="9.99698557391836E-07"
        ixy="-2.18278347694959E-08"
        ixz="1.56085772683329E-08"
        iyy="6.10313699066286E-07"
        iyz="3.14479371620686E-07"
        izz="7.98354669596689E-07" />
    </inertial>
    <visual>
      <origin
        xyz="0 0 0"
        rpy="0 0 0" />
      <geometry>
        <mesh
          filename="P_B_MCP.STL" />
      </geometry>
      <material
        name="">
        <color
          rgba="0.698039215686274 0.698039215686274 0.698039215686274 1" />
      </material>
    </visual>
    <collision>
      <origin
        xyz="0 0 0"
        rpy="0 0 0" />
      <geometry>
        <mesh
          filename="P_B_MCP.STL" />
      </geometry>
    </collision>
  </link>
  <joint
    name="P_B_MCP"
    type="revolute">
    <origin
      xyz="0 -0.0314999999999991 0.101"
      rpy="1.5707963267949 0 1.5707963267949" />
    <parent
      link="Palm_Base" />
    <child
      link="P_B_MCP" />
    <axis
      xyz="0 0 1" />
    <limit
      lower="0"
      upper="0.6872"
      effort="0"
      velocity="0" />
  </joint>
  <link
    name="P_MCP">
    <inertial>
      <origin
        xyz="1.75554955950188E-05 0.0123862857722916 -0.00586906537761576"
        rpy="0 0 0" />
      <mass
        value="0.00275274576508524" />
      <inertia
        ixx="3.66135316485623E-07"
        ixy="5.22812137872017E-11"
        ixz="5.20268126523517E-11"
        iyy="2.51983299258902E-07"
        iyz="-4.56232322526551E-08"
        izz="3.63835747168657E-07" />
    </inertial>
    <visual>
      <origin
        xyz="0 0 0"
        rpy="0 0 0" />
      <geometry>
        <mesh
          filename="P_MCP.STL" />
      </geometry>
      <material
        name="">
        <color
          rgba="0.796078431372549 0.823529411764706 0.937254901960784 1" />
      </material>
    </visual>
    <collision>
      <origin
        xyz="0 0 0"
        rpy="0 0 0" />
      <geometry>
        <mesh
          filename="P_MCP.STL" />
      </geometry>
    </collision>
  </link>
  <joint
    name="P_MCP"
    type="revolute">
    <origin
      xyz="0 0.028 -0.0104999999999996"
      rpy="-3.14159265358979 0 3.14159265358979" />
    <parent
      link="P_B_MCP" />
    <child
      link="P_MCP" />
    <axis
      xyz="-1 0 0" />
    <limit
      upper="1.7269"
      lower="0"
      effort="0"
      velocity="0" />
  </joint>
  <link
    name="P_PIP">
    <inertial>
      <origin
        xyz="1.74613939576754E-05 0.0103551539568031 -0.00633662510888215"
        rpy="0 0 0" />
      <mass
        value="0.00234098594407861" />
      <inertia
        ixx="2.36046453580125E-07"
        ixy="-1.81481552815254E-11"
        ixz="6.62320590883984E-11"
        iyy="2.01338905932991E-07"
        iyz="-3.58240052840699E-09"
        izz="2.29068935661679E-07" />
    </inertial>
    <visual>
      <origin
        xyz="0 0 0"
        rpy="0 0 0" />
      <geometry>
        <mesh
          filename="P_PIP.STL" />
      </geometry>
      <material
        name="">
        <color
          rgba="0.796078431372549 0.823529411764706 0.937254901960784 1" />
      </material>
    </visual>
    <collision>
      <origin
        xyz="0 0 0"
        rpy="0 0 0" />
      <geometry>
        <mesh
          filename="P_PIP.STL" />
      </geometry>
    </collision>
  </link>
  <joint
    name="P_PIP"
    type="revolute">
    <origin
      xyz="0 0.0349845407392164 -4.41133227819367E-05"
      rpy="0 0 0" />
    <parent
      link="P_MCP" />
    <child
      link="P_PIP" />
    <axis
      xyz="-1 0 0" />
    <limit
      upper="1.2573"
      lower="0"
      effort="0"
      velocity="0" />
  </joint>
  <link
    name="P_DIP">
    <inertial>
      <origin
        xyz="0.00857257995714257 0.015216338744899 2.31261281485526E-05"
        rpy="0 0 0" />
      <mass
        value="0.0031086176238361" />
      <inertia
        ixx="3.21156100189876E-07"
        ixy="-4.50241052565898E-08"
        ixz="7.08906803239545E-12"
        iyy="1.56377769878685E-07"
        iyz="7.86097567047071E-12"
        izz="3.02201695484807E-07" />
    </inertial>
    <visual>
      <origin
        xyz="0 0 0"
        rpy="0 0 0" />
      <geometry>
        <mesh
          filename="P_DIP.STL" />
      </geometry>
      <material
        name="">
        <color
          rgba="0.796078431372549 0.823529411764706 0.937254901960784 1" />
      </material>
    </visual>
    <collision>
      <origin
        xyz="0 0 0"
        rpy="0 0 0" />
      <geometry>
        <mesh
          filename="P_DIP.STL" />
      </geometry>
    </collision>
  </link>
  <joint
    name="P_DIP"
    type="revolute">
    <origin
      xyz="0 0.028 0"
      rpy="0 1.5707963267949 0" />
    <parent
      link="P_PIP" />
    <child
      link="P_DIP" />
    <axis
      xyz="0 0 -1" />
    <limit
      upper="1.2577"
      lower="0"
      effort="0"
      velocity="0" />
  </joint>
  <link
    name="P_DIP_TIP">
    <inertial>
      <origin
        xyz="-0.00142742008351409 -0.0152836613401574 2.31261185003676E-05"
        rpy="0 0 0" />
      <mass
        value="0.00310861760480009" />
      <inertia
        ixx="3.21156096904448E-07"
        ixy="-4.50241043703727E-08"
        ixz="7.0897587779266E-12"
        iyy="1.56377770371452E-07"
        iyz="7.86133288174135E-12"
        izz="3.02201692226518E-07" />
    </inertial>
    <visual>
      <origin
        xyz="0 0 0"
        rpy="0 0 0" />
      <geometry>
        <mesh
          filename="P_DIP_TIP.STL" />
      </geometry>
      <material
        name="">
        <color
          rgba="0.796078431372549 0.823529411764706 0.937254901960784 1" />
      </material>
    </visual>
    <collision>
      <origin
        xyz="0 0 0"
        rpy="0 0 0" />
      <geometry>
        <mesh
          filename="P_DIP_TIP.STL" />
      </geometry>
    </collision>
  </link>
  <joint
    name="P_DIP_tip"
    type="fixed">
    <origin
      xyz="0.00999999999999945 0.0304999999999999 0"
      rpy="0 0 0" />
    <parent
      link="P_DIP" />
    <child
      link="P_DIP_TIP" />
    <axis
      xyz="0 0 0" />
  </joint>
</robot>
